Workbook

Sheet Year_2025
A1: TotalPoints | B1: Spread | C1: HomeWin | D1: season | E1: week | F1: team | G1: HomeTeamName | H1: opponent_team | I1: AwayTeamName | J1: NuetralSite | K1: DivisionCompetition | L1: ConferenceCompetition | M1: HomeWinner | N1: HomeWins | O1: HomeLosses | P1: HomeAveragePointsAgainst | Q1: HomeAveragePointsFor | R1: HomePointDifferential | S1: HomeStreak | T1: HomeWinPercent | U1: HomeDivisionWins | V1: HomeDivisionLosses | W1: HomeTeamHomeWins | X1: HomeTeamHomeLosses | Y1: HomeTeamAwayWins | Z1: HomeTeamAwayLosses | AA1: HomeConferenceWins | AB1: HomeConferenceLosses | AC1: HomeTeamMlWins | AD1: HomeTeamMlLosses | AE1: HomeTeamSpreadWins | AF1: HomeTeamSpreadLosses | AG1: HomeInjuryCount | AH1: AwayWinner | AI1: AwayWins | AJ1: AwayLosses | AK1: AwayAveragePointsAgainst | AL1: AwayAveragePointsFor | AM1: AwayPointDifferential | AN1: AwayStreak | AO1: AwayWinPercent | AP1: AwayDivisionWins | AQ1: AwayDivisionLosses | AR1: AwayTeamHomeWins | AS1: AwayTeamHomeLosses | AT1: AwayTeamAwayWins | AU1: AwayTeamAwayLosses | AV1: AwayConferenceWins | AW1: AwayConferenceLosses | AX1: AwayTeamMlWins | AY1: AwayTeamMlLosses | AZ1: AwayTeamSpreadWins | BA1: AwayTeamSpreadLosses | BB1: AwayInjuryCount | BC1: AveragePredictedTotal | BD1: AveragePredictedSpread | BE1: MoneyLineWinner | BF1: SpreadWinner | BG1: PredictedHomeWinPercent | BH1: PredicitedHomeMatchupQuality | BI1: PredictedHomeLossPercent | BJ1: PredictedHomeDefenseEfficiency | BK1: PredictedHomeOffenseEfficiency | BL1: PredictedHomeTotalEfficiency | BM1: PredictedHomePointDifferential | BN1: PredictedAwayWinPercent | BO1: PredicitedAwayMatchupQuality | BP1: PredictedAwayOpponentStrenth | BQ1: PredictedAwayLossPercent | BR1: PredictedAwayPointDifferential | BS1: PredictedAwayDefenseEfficiency | BT1: PredictedAwayOffenseEfficiency | BU1: PredictedAwayTotalEfficiency | BV1: HomeQbr | BW1: HomeCompletionPercent | BX1: HomeNetPassYardsPerGame | BY1: HomePassingBigPlays | BZ1: HomeScrimmageYardsPerGame | CA1: HomeYardsPerPassAttempt | CB1: HomeRbRating | CC1: HomeRushYardsPerGame | CD1: HomeYardsPerRushAttempt | CE1: HomeRushingTouchdowns | CF1: HomeWrRating | CG1: HomeReceivingTouchdowns | CH1: HomeReceivingYardsPerGame | CI1: HomeReceivingYardsPerReception | CJ1: HomeAverageSackYards | CK1: HomeAverageStuffYards | CL1: HomeDefensiveTouchdowns | CM1: HomeSacks | CN1: HomeYardsAllowed | CO1: HomeExtraPointPercentage | CP1: HomeFieldGoalPercent | CQ1: HomeFieldGoalsMade | CR1: HomeTotalKickingPoints | CS1: HomeNetAveragePuntYards | CT1: HomeTotalPunts | CU1: HomePuntsInsideTwenty | CV1: HomeDefensivePoints | CW1: HomePassingTouchdowns | CX1: HomeTotalPoints | CY1: HomeFirstDownsPerGame | CZ1: HomeFourthDownConversionPercent | DA1: HomeThirdDownConversionPercent | DB1: HomeRedZoneEfficiencyPercent | DC1: HomeTurnoverDifferential | DD1: AwayQbr | DE1: AwayCompletionPercent | DF1: AwayNetPassYardsPerGame | DG1: AwayPassingBigPlays | DH1: AwayScrimmageYardsPerGame | DI1: AwayYardsPerPassAttempt | DJ1: AwayRbRating | DK1: AwayRushYardsPerGame | DL1: AwayYardsPerRushAttempt | DM1: AwayRushingTouchdowns | DN1: AwayWrRating | DO1: AwayReceivingTouchdowns | DP1: AwayReceivingYardsPerGame | DQ1: AwayReceivingYardsPerReception | DR1: AwayAverageSackYards | DS1: AwayAverageStuffYards | DT1: AwayDefensiveTouchdowns | DU1: AwaySacks | DV1: AwayYardsAllowed | DW1: AwayExtraPointPercentage | DX1: AwayFieldGoalPercent | DY1: AwayFieldGoalsMade | DZ1: AwayTotalKickingPoints | EA1: AwayNetAveragePuntYards | EB1: AwayPuntsInsideTwenty | EC1: AwayTotalPunts | ED1: AwayDefensivePoints | EE1: AwayPassingTouchdowns | EF1: AwayTotalPoints | EG1: AwayFirstDownsPerGame | EH1: AwayFourthDownConversionPercent | EI1: AwayThirdDownConversionPercent | EJ1: AwayRedZoneEfficiencyPercent | EK1: AwayTurnoverDifferential
A2: 44 | B2: 4 | C2: 1 | D2: 2025 | E2: 1 | F2: =VLOOKUP(G2, Map!$A$1:$B$33, 2, FALSE) -> PHI | G2: Eagles | H2: =VLOOKUP(I2, Map!$A$1:$B$33, 2, FALSE) -> DAL | I2: Cowboys | J2: 0 | K2: 0 | L2: 0 | M2: 1 | N2: 6 | O2: 2 | P2: 23.125 | Q2: 26 | R2: 23 | S2: 2 | T2: 0.75 | U2: 2 | V2: 1 | W2: 3 | X2: 1 | Y2: 3 | Z2: 1 | AA2: 5 | AB2: 1 | AC2: 16 | AD2: 3 | AE2: 10 | AF2: 9 | AG2: 63 | AH2: 0 | AI2: 3 | AJ2: 4 | AK2: 31.25 | AL2: 30.75 | AM2: -4 | AN2: -1 | AO2: 0.4375 | AP2: 2 | AQ2: 1 | AR2: 2 | AS2: 0 | AT2: 1 | AU2: 4 | AV2: 2 | AW2: 3 | AX2: 13 | AY2: 5 | AZ2: 11 | BA2: 7 | BB2: 68 | BC2: 46 | BD2: -6 | BE2: 0 | BF2: 0 | BG2: 67.47 | BH2: 64.041 | BI2: 32.27 | BJ2: 40.889 | BK2: 77.242 | BL2: 62.405 | BM2: 7.572 | BN2: 32.27 | BO2: 64.041 | BP2: 0 | BQ2: 67.47 | BR2: -7.572 | BS2: 22.758 | BT2: 59.111 | BU2: 37.595 | BV2: 2679 | BW2: 70.233 | BX2: 192.75 | BY2: 23 | BZ2: 321.25 | CA2: 7.716 | CB2: 1178 | CC2: 111.625 | CD2: 4.096 | CE2: 9 | CF2: 2957 | CG2: 15 | CH2: 209.625 | CI2: 10.987 | CJ2: 4.75 | CK2: 3.75 | CL2: 3 | CM2: 16 | CN2: 0 | CO2: 100 | CP2: 77.778 | CQ2: 7 | CR2: 46 | CS2: 13.55 | CT2: 34 | CU2: 7 | CV2: 6 | CW2: 15 | CX2: 208 | CY2: 17.875 | CZ2: 78.571 | DA2: 33.333 | DB2: 87.14 | DC2: 4 | DD2: 3160 | DE2: 70.234 | DF2: 263.75 | DG2: 25 | DH2: 391.375 | DI2: 7.191 | DJ2: 1283 | DK2: 120.375 | DL2: 4.675 | DM2: 10 | DN2: 3813 | DO2: 17 | DP2: 271 | DQ2: 10.238 | DR2: 7.733 | DS2: 4.81 | DT2: 1 | DU2: 15 | DV2: 0 | DW2: 96.296 | DX2: 100 | DY2: 16 | DZ2: 74 | EA2: 10 | EB2: 11 | EC2: 28 | ED2: 6 | EE2: 17 | EF2: 246 | EG2: 23.125 | EH2: 77.778 | EI2: 43.158 | EJ2: 74.19 | EK2: -1
A3: 48 | B3: 6 | C3: 1 | D3: 2025 | E3: 1 | F3: =VLOOKUP(G3, Map!$A$1:$B$33, 2, FALSE) -> LAC | G3: Chargers | H3: =VLOOKUP(I3, Map!$A$1:$B$33, 2, FALSE) -> KC | I3: Chiefs | J3: 0 | K3: 0 | L3: 0 | M3: 1 | N3: 5 | O3: 3 | P3: 21.625 | Q3: 23.5 | R3: 15 | S3: 1 | T3: 0.625 | U3: 3 | V3: 0 | W3: 3 | X3: 2 | Y3: 2 | Z3: 1 | AA3: 4 | AB3: 1 | AC3: 10 | AD3: 7 | AE3: 11 | AF3: 5 | AG3: 65 | AH3: 0 | AI3: 5 | AJ3: 3 | AK3: 16.375 | AL3: 26.75 | AM3: 83 | AN3: 3 | AO3: 0.625 | AP3: 1 | AQ3: 1 | AR3: 4 | AS3: 1 | AT3: 1 | AU3: 2 | AV3: 2 | AW3: 2 | AX3: 16 | AY3: 3 | AZ3: 7 | BA3: 11 | BB3: 65 | BC3: 49.5 | BD3: 0 | BE3: 0 | BF3: 0 | BG3: 42.363 | BH3: 75.987 | BI3: 57.297 | BJ3: 43.684 | BK3: 83.054 | BL3: 69.27 | BM3: -2.771 | BN3: 57.297 | BO3: 75.987 | BP3: 0 | BQ3: 42.363 | BR3: 2.771 | BS3: 16.946 | BT3: 56.316 | BU3: 30.73 | BV3: 3094 | BW3: 68 | BX3: 255.375 | BY3: 26 | BZ3: 396.125 | CA3: 7.28 | CB3: 1030 | CC3: 123.125 | CD3: 4.852 | CE3: 3 | CF3: 3764 | CG3: 16 | CH3: 273 | CI3: 10.706 | CJ3: 5.591 | CK3: 5.05 | CL3: 0 | CM3: 22 | CN3: 0 | CO3: 100 | CP3: 94.737 | CQ3: 18 | CR3: 72 | CS3: 12.5 | CT3: 20 | CU3: 8 | CV3: 0 | CW3: 16 | CX3: 188 | CY3: 21.875 | CZ3: 70 | DA3: 48.673 | DB3: 61.73 | DC3: -3 | DD3: 3149 | DE3: 67.021 | DF3: 251.75 | DG3: 25 | DH3: 388.875 | DI3: 7.372 | DJ3: 1327 | DK3: 126.5 | DL3: 4.498 | DM3: 9 | DN3: 3639 | DO3: 17 | DP3: 262.375 | DQ3: 11 | DR3: 4 | DS3: 3.4 | DT3: 0 | DU3: 17 | DV3: 0 | DW3: 88 | DX3: 80 | DY3: 12 | DZ3: 58 | EA3: 8.333 | EB3: 11 | EC3: 19 | ED3: 0 | EE3: 17 | EF3: 214 | EG3: 23.625 | EH3: 82.353 | EI3: 44 | EJ3: 78.15 | EK3: 5
A4: 43 | B4: -3 | C4: 0 | D4: 2025 | E4: 1 | F4: =VLOOKUP(G4, Map!$A$1:$B$33, 2, FALSE) -> ATL | G4: Falcons | H4: =VLOOKUP(I4, Map!$A$1:$B$33, 2, FALSE) -> TB | I4: Buccaneers | J4: 0 | K4: 0 | L4: 0 | M4: 0 | N4: 3 | O4: 4 | P4: 22 | Q4: 17.142857 | R4: -34 | S4: -2 | T4: 0.42857143 | U4: 0 | V4: 2 | W4: 2 | X4: 2 | Y4: 1 | Z4: 2 | AA4: 2 | AB4: 3 | AC4: 7 | AD4: 10 | AE4: 9 | AF4: 8 | AG4: 64 | AH4: 1 | AI4: 6 | AJ4: 2 | AK4: 22.25 | AL4: 24.625 | AM4: 19 | AN4: 1 | AO4: 0.75 | AP4: 2 | AQ4: 0 | AR4: 2 | AS4: 1 | AT4: 4 | AU4: 1 | AV4: 4 | AW4: 2 | AX4: 8 | AY4: 9 | AZ4: 4 | BA4: 12 | BB4: 59 | BC4: 45 | BD4: -2 | BE4: 0 | BF4: 0 | BG4: 44.023 | BH4: 43.179 | BI4: 55.623 | BJ4: 24.259 | BK4: 60.414 | BL4: 41.888 | BM4: -2.07 | BN4: 55.623 | BO4: 43.179 | BP4: 0 | BQ4: 44.023 | BR4: 2.07 | BS4: 39.586 | BT4: 75.741 | BU4: 58.112 | BV4: 1871 | BW4: 62.232 | BX4: 219.42857 | BY4: 19 | BZ4: 353.42856 | CA4: 6.914 | CB4: 1048 | CC4: 123.286 | CD4: 4.403 | CE4: 7 | CF4: 2511 | CG4: 5 | CH4: 230.143 | CI4: 11.11 | CJ4: 5.938 | CK4: 5.643 | CL4: 0 | CM4: 16 | CN4: 0 | CO4: 100 | CP4: 75 | CQ4: 12 | CR4: 48 | CS4: 7.538 | CT4: 22 | CU4: 9 | CV4: 0 | CW4: 5 | CX4: 120 | CY4: 19.286 | CZ4: 40 | DA4: 39.326 | DB4: 57.86 | DC4: 2 | DD4: 2769 | DE4: 63.941 | DF4: 224.875 | DG4: 29 | DH4: 338 | DI4: 7.134 | DJ4: 950 | DK4: 98.125 | DL4: 3.848 | DM4: 6 | DN4: 3234 | DO4: 13 | DP4: 239.875 | DQ4: 11.157 | DR4: 7.8 | DS4: 6.8 | DT4: 2 | DU4: 25 | DV4: 0 | DW4: 94.118 | DX4: 80.952 | DY4: 17 | DZ4: 67 | EA4: 14.667 | EB4: 12 | EC4: 32 | ED4: 14 | EE4: 13 | EF4: 197 | EG4: 18.875 | EH4: 50 | EI4: 36.275 | EJ4: 55.19 | EK4: 7
A5: 33 | B5: -1 | C5: 0 | D5: 2025 | E5: 1 | F5: =VLOOKUP(G5, Map!$A$1:$B$33, 2, FALSE) -> CLE | G5: Browns | H5: =VLOOKUP(I5, Map!$A$1:$B$33, 2, FALSE) -> CIN | I5: Bengals | J5: 0 | K5: 0 | L5: 0 | M5: 0 | N5: 2 | O5: 6 | P5: 23 | Q5: 15.75 | R5: -58 | S5: -1 | T5: 0.25 | U5: 0 | V5: 3 | W5: 2 | X5: 2 | Y5: 0 | Z5: 4 | AA5: 1 | AB5: 4 | AC5: 7 | AD5: 10 | AE5: 8 | AF5: 9 | AG5: 61 | AH5: 1 | AI5: 3 | AJ5: 5 | AK5: 31.625 | AL5: 21.75 | AM5: -79 | AN5: -1 | AO5: 0.375 | AP5: 2 | AQ5: 0 | AR5: 2 | AS5: 2 | AT5: 1 | AU5: 3 | AV5: 3 | AW5: 2 | AX5: 14 | AY5: 4 | AZ5: 13 | BA5: 5 | BB5: 59 | BC5: 43 | BD5: 2 | BE5: 0 | BF5: 0 | BG5: 35.723 | BH5: 42.871 | BI5: 63.99 | BJ5: 65.486 | BK5: 38.131 | BL5: 46.24 | BM5: -5.884 | BN5: 63.99 | BO5: 42.871 | BP5: 0 | BQ5: 35.723 | BR5: 5.884 | BS5: 61.869 | BT5: 34.514 | BU5: 53.76 | BV5: 1756 | BW5: 58.94 | BX5: 174.125 | BY5: 14 | BZ5: 279.125 | CA5: 4.987 | CB5: 896 | CC5: 89.5 | CD5: 3.768 | CE5: 6 | CF5: 2652 | CG5: 7 | CH5: 189.625 | CI5: 8.461 | CJ5: 6.917 | CK5: 4.303 | CL5: 1 | CM5: 24 | CN5: 0 | CO5: 92.308 | CP5: 76.923 | CQ5: 10 | CR5: 42 | CS5: 11.412 | CT5: 42 | CU5: 16 | CV5: 6 | CW5: 7 | CX5: 126 | CY5: 16.75 | CZ5: 57.895 | DA5: 33.043 | DB5: 69.39 | DC5: 0 | DD5: 2540 | DE5: 63.636 | DF5: 202 | DG5: 15 | DH5: 299.125 | DI5: 6.049 | DJ5: 793 | DK5: 82.875 | DL5: 4.305 | DM5: 5 | DN5: 3165 | DO5: 15 | DP5: 216.25 | DQ5: 9.505 | DR5: 5.273 | DS5: 3.357 | DT5: 0 | DU5: 11 | DV5: 0 | DW5: 100 | DX5: 84.615 | DY5: 11 | DZ5: 52 | EA5: 11.524 | EB5: 11 | EC5: 37 | ED5: 0 | EE5: 15 | EF5: 174 | EG5: 18.5 | EH5: 80 | EI5: 39.394 | EJ5: 79.87 | EK5: -2
A6: 41 | B6: 25 | C6: 1 | D6: 2025 | E6: 1 | F6: =VLOOKUP(G6, Map!$A$1:$B$33, 2, FALSE) -> IND | G6: Colts | H6: =VLOOKUP(I6, Map!$A$1:$B$33, 2, FALSE) -> MIA | I6: Dolphins | J6: 0 | K6: 0 | L6: 0 | M6: 1 | N6: 7 | O6: 1 | P6: 19.25 | Q6: 33.75 | R6: 116 | S6: 4 | T6: 0.875 | U6: 2 | V6: 0 | W6: 5 | X6: 0 | Y6: 2 | Z6: 1 | AA6: 6 | AB6: 0 | AC6: 4 | AD6: 12 | AE6: 6 | AF6: 11 | AG6: 68 | AH6: 0 | AI6: 2 | AJ6: 6 | AK6: 26.875 | AL6: 21.75 | AM6: -41 | AN6: 1 | AO6: 0.25 | AP6: 1 | AQ6: 2 | AR6: 1 | AS6: 2 | AT6: 1 | AU6: 4 | AV6: 1 | AW6: 5 | AX6: 9 | AY6: 9 | AZ6: 10 | BA6: 8 | BB6: 68 | BC6: 44.5 | BD6: -13 | BE6: 0 | BF6: 0 | BG6: 52.21 | BH6: 36.923 | BI6: 47.41 | BJ6: 98.326 | BK6: 87.314 | BL6: 98.343 | BM6: 0.929 | BN6: 47.41 | BO6: 36.923 | BP6: 0 | BQ6: 52.21 | BR6: -0.929 | BS6: 12.686 | BT6: 1.674 | BU6: 1.657 | BV6: 2891 | BW6: 70.161 | BX6: 250.875 | BY6: 23 | BZ6: 393.25 | CA6: 8.351 | CB6: 1690 | CC6: 134.375 | CD6: 5.023 | CE6: 18 | CF6: 3396 | CG6: 13 | CH6: 258.875 | CI6: 11.902 | CJ6: 6.826 | CK6: 6.091 | CL6: 1 | CM6: 23 | CN6: 0 | CO6: 96.296 | CP6: 94.118 | CQ6: 16 | CR6: 74 | CS6: 4.25 | CT6: 16 | CU6: 8 | CV6: 6 | CW6: 13 | CX6: 270 | CY6: 23.25 | CZ6: 83.333 | DA6: 45.349 | DB6: 77.07 | DC6: 8 | DD6: 2361 | DE6: 68.675 | DF6: 187.875 | DG6: 17 | DH6: 299.875 | DI6: 6.47 | DJ6: 898 | DK6: 98.5 | DL6: 4.452 | DM6: 4 | DN6: 2991 | DO6: 15 | DP6: 201.375 | DQ6: 9.421 | DR6: 6.467 | DS6: 4.824 | DT6: 1 | DU6: 15 | DV6: 0 | DW6: 100 | DX6: 91.667 | DY6: 11 | DZ6: 52 | EA6: 7 | EB6: 11 | EC6: 26 | ED6: 6 | EE6: 15 | EF6: 174 | EG6: 17 | EH6: 53.846 | EI6: 41.237 | EJ6: 72.05 | EK6: -5
A7: 33 | B7: -7 | C7: 0 | D7: 2025 | E7: 1 | F7: =VLOOKUP(G7, Map!$A$1:$B$33, 2, FALSE) -> NE | G7: Patriots | H7: =VLOOKUP(I7, Map!$A$1:$B$33, 2, FALSE) -> LV | I7: Raiders | J7: 0 | K7: 0 | L7: 0 | M7: 0 | N7: 6 | O7: 2 | P7: 18.25 | Q7: 26.625 | R7: 67 | S7: 5 | T7: 0.75 | U7: 2 | V7: 0 | W7: 2 | X7: 2 | Y7: 4 | Z7: 0 | AA7: 4 | AB7: 2 | AC7: 8 | AD7: 9 | AE7: 7 | AF7: 9 | AG7: 61 | AH7: 1 | AI7: 2 | AJ7: 5 | AK7: 25.714285 | AL7: 14.714286 | AM7: -77 | AN7: -1 | AO7: 0.2857143 | AP7: 0 | AQ7: 2 | AR7: 1 | AS7: 2 | AT7: 1 | AU7: 3 | AV7: 2 | AW7: 3 | AX7: 6 | AY7: 10 | AZ7: 8 | BA7: 8 | BB7: 56 | BC7: 40 | BD7: 4 | BE7: 0 | BF7: 0 | BG7: 51.339 | BH7: 32.275 | BI7: 48.273 | BJ7: 33.497 | BK7: 37.097 | BL7: 28.852 | BM7: 0.748 | BN7: 48.273 | BO7: 32.275 | BP7: 0 | BQ7: 51.339 | BR7: -0.748 | BS7: 62.903 | BT7: 66.503 | BU7: 71.148 | BV7: 2965 | BW7: 75 | BX7: 240.5 | BY7: 29 | BZ7: 367.375 | CA7: 8.794 | CB7: 1056 | CC7: 112.625 | CD7: 3.934 | CE7: 7 | CF7: 3418 | CG7: 15 | CH7: 254.75 | CI7: 11.725 | CJ7: 6.316 | CK7: 3.741 | CL7: 4 | CM7: 19 | CN7: 0 | CO7: 91.304 | CP7: 92.308 | CQ7: 12 | CR7: 57 | CS7: 16.8 | CT7: 27 | CU7: 10 | CV7: 14 | CW7: 15 | CX7: 213 | CY7: 20.375 | CZ7: 83.333 | DA7: 39.785 | DB7: 67 | DC7: 2 | DD7: 1570 | DE7: 66.176 | DF7: 182.71428 | DG7: 19 | DH7: 297.2857 | DI7: 6.765 | DJ7: 731 | DK7: 93.714 | DL7: 3.859 | DM7: 3 | DN7: 2345 | DO7: 7 | DP7: 203.571 | DQ7: 10.222 | DR7: 6.733 | DS7: 3.071 | DT7: 0 | DU7: 15 | DV7: 0 | DW7: 100 | DX7: 78.571 | DY7: 11 | DZ7: 41 | EA7: 15.333 | EB7: 8 | EC7: 26 | ED7: 0 | EE7: 7 | EF7: 103 | EG7: 15.857 | EH7: 45.455 | EI7: 37.931 | EJ7: 53.17 | EK7: -5
A8: 33 | B8: -7 | C8: 0 | D8: 2025 | E8: 1 | F8: =VLOOKUP(G8, Map!$A$1:$B$33, 2, FALSE) -> NO | G8: Saints | H8: =VLOOKUP(I8, Map!$A$1:$B$33, 2, FALSE) -> ARI | I8: Cardinals | J8: 0 | K8: 0 | L8: 0 | M8: 0 | N8: 1 | O8: 7 | P8: 26.125 | Q8: 16 | R8: -81 | S8: -3 | T8: 0.125 | U8: 0 | V8: 1 | W8: 1 | X8: 4 | Y8: 0 | Z8: 3 | AA8: 1 | AB8: 5 | AC8: 7 | AD8: 10 | AE8: 7 | AF8: 10 | AG8: 64 | AH8: 1 | AI8: 2 | AJ8: 5 | AK8: 22 | AL8: 21.857143 | AM8: -1 | AN8: -5 | AO8: 0.2857143 | AP8: 0 | AQ8: 2 | AR8: 1 | AS8: 3 | AT8: 1 | AU8: 2 | AV8: 2 | AW8: 3 | AX8: 4 | AY8: 12 | AZ8: 8 | BA8: 8 | BB8: 69 | BC8: 41 | BD8: 4.5 | BE8: 0 | BF8: 0 | BG8: 41.434 | BH8: 30.07 | BI8: 58.234 | BJ8: 33.129 | BK8: 44.441 | BL8: 29.829 | BM8: -3.281 | BN8: 58.234 | BO8: 30.07 | BP8: 0 | BQ8: 41.434 | BR8: 3.281 | BS8: 55.559 | BT8: 66.871 | BU8: 70.171 | BV8: 2083 | BW8: 66.207 | BX8: 201.375 | BY8: 13 | BZ8: 310.25 | CA8: 5.976 | CB8: 779 | CC8: 93.625 | CD8: 3.783 | CE8: 3 | CF8: 2973 | CG8: 8 | CH8: 216.625 | CI8: 9.026 | CJ8: 6.059 | CK8: 4.778 | CL8: 1 | CM8: 17 | CN8: 0 | CO8: 100 | CP8: 71.429 | CQ8: 15 | CR8: 56 | CS8: 15.25 | CT8: 27 | CU8: 7 | CV8: 6 | CW8: 8 | CX8: 128 | CY8: 19.125 | CZ8: 33.333 | DA8: 38.835 | DB8: 61.22 | DC8: -2 | DD8: 2113 | DE8: 66.942 | DF8: 199.85715 | DG8: 18 | DH8: 333.42856 | DI8: 6.335 | DJ8: 888 | DK8: 110.429 | DL8: 4.417 | DM8: 5 | DN8: 2721 | DO8: 10 | DP8: 223 | DQ8: 9.463 | DR8: 6.667 | DS8: 3.238 | DT8: 1 | DU8: 12 | DV8: 0 | DW8: 100 | DX8: 86.667 | DY8: 13 | DZ8: 55 | EA8: 8.25 | EB8: 9 | EC8: 25 | ED8: 8 | EE8: 10 | EF8: 153 | EG8: 19 | EH8: 57.143 | EI8: 44.792 | EJ8: 63.49 | EK8: -1
A9: 66 | B9: -2 | C9: 0 | D9: 2025 | E9: 1 | F9: =VLOOKUP(G9, Map!$A$1:$B$33, 2, FALSE) -> NYJ | G9: Jets | H9: =VLOOKUP(I9, Map!$A$1:$B$33, 2, FALSE) -> PIT | I9: Steelers | J9: 0 | K9: 0 | L9: 0 | M9: 0 | N9: 1 | O9: 7 | P9: 27.625 | Q9: 21 | R9: -53 | S9: 1 | T9: 0.125 | U9: 0 | V9: 2 | W9: 0 | X9: 5 | Y9: 1 | Z9: 2 | AA9: 1 | AB9: 4 | AC9: 7 | AD9: 10 | AE9: 8 | AF9: 9 | AG9: 60 | AH9: 1 | AI9: 4 | AJ9: 3 | AK9: 25 | AL9: 25 | AM9: 0 | AN9: -2 | AO9: 0.5714286 | AP9: 1 | AQ9: 1 | AR9: 2 | AS9: 2 | AT9: 2 | AU9: 1 | AV9: 3 | AW9: 1 | AX9: 9 | AY9: 8 | AZ9: 10 | BA9: 6 | BB9: 66 | BC9: 51 | BD9: 2 | BE9: 0 | BF9: 0 | BG9: 41.434 | BH9: 36.137 | BI9: 58.234 | BJ9: 24.87 | BK9: 76.346 | BL9: 41.368 | BM9: -3.529 | BN9: 58.234 | BO9: 36.137 | BP9: 0 | BQ9: 41.434 | BR9: 3.529 | BS9: 23.654 | BT9: 75.13 | BU9: 58.632 | BV9: 2012 | BW9: 63.713 | BX9: 156.5 | BY9: 15 | BZ9: 327.625 | CA9: 6.211 | CB9: 1254 | CC9: 143.625 | CD9: 5.199 | CE9: 6 | CF9: 2542 | CG9: 9 | CH9: 184 | CI9: 9.748 | CJ9: 6.273 | CK9: 2.417 | CL9: 1 | CM9: 11 | CN9: 0 | CO9: 100 | CP9: 100 | CQ9: 17 | CR9: 60 | CS9: 6.25 | CT9: 31 | CU9: 11 | CV9: 2 | CW9: 9 | CX9: 168 | CY9: 18.5 | CZ9: 52.632 | DA9: 34.906 | DB9: 69.17 | DC9: -9 | DD9: 2471 | DE9: 68.571 | DF9: 202.85715 | DG9: 20 | DH9: 308.7143 | DI9: 7.148 | DJ9: 750 | DK9: 94.286 | DL9: 4.074 | DM9: 3 | DN9: 2781 | DO9: 16 | DP9: 214.429 | DQ9: 10.424 | DR9: 6.409 | DS9: 7.438 | DT9: 0 | DU9: 22 | DV9: 0 | DW9: 100 | DX9: 87.5 | DY9: 14 | DZ9: 59 | EA9: 8.25 | EB9: 8 | EC9: 23 | ED9: 0 | EE9: 16 | EF9: 175 | EG9: 17.429 | EH9: 50 | EI9: 38.961 | EJ9: 75.94 | EK9: 4
A10: 27 | B10: 15 | C10: 1 | D10: 2025 | E10: 1 | F10: =VLOOKUP(G10, Map!$A$1:$B$33, 2, FALSE) -> WAS | G10: Commanders | H10: =VLOOKUP(I10, Map!$A$1:$B$33, 2, FALSE) -> NYG | I10: Giants | J10: 0 | K10: 0 | L10: 0 | M10: 1 | N10: 3 | O10: 5 | P10: 24.75 | Q10: 23.375 | R10: -11 | S10: -3 | T10: 0.375 | U10: 1 | V10: 1 | W10: 2 | X10: 1 | Y10: 1 | Z10: 4 | AA10: 1 | AB10: 4 | AC10: 7 | AD10: 8 | AE10: 7 | AF10: 8 | AG10: 65 | AH10: 0 | AI10: 2 | AJ10: 6 | AK10: 26.875 | AL10: 21.625 | AM10: -42 | AN10: -2 | AO10: 0.25 | AP10: 1 | AQ10: 3 | AR10: 2 | AS10: 1 | AT10: 0 | AU10: 5 | AV10: 1 | AW10: 4 | AX10: 10 | AY10: 7 | AZ10: 14 | BA10: 4 | BB10: 67 | BC10: 39 | BD10: -8.5 | BE10: 0 | BF10: 0 | BG10: 67.537 | BH10: 45.614 | BI10: 32.204 | BJ10: 76.826 | BK10: 67.76 | BL10: 81.373 | BM10: 7.241 | BN10: 32.204 | BO10: 45.614 | BP10: 0 | BQ10: 67.537 | BR10: -7.241 | BS10: 32.24 | BT10: 23.174 | BU10: 18.627 | BV10: 2360 | BW10: 61.966 | BX10: 196.625 | BY10: 20 | BZ10: 346.5 | CA10: 7.137 | CB10: 1342 | CC10: 137.75 | CD10: 5.198 | CE10: 9 | CF10: 2815 | CG10: 12 | CH10: 208.75 | CI10: 11.517 | CJ10: 6.136 | CK10: 5.947 | CL10: 1 | CM10: 22 | CN10: 0 | CO10: 100 | CP10: 71.429 | CQ10: 10 | CR10: 49 | CS10: 4 | CT10: 25 | CU10: 11 | CV10: 8 | CW10: 12 | CX10: 187 | CY10: 18.75 | CZ10: 45.455 | DA10: 38.636 | DB10: 79.29 | DC10: -5 | DD10: 2348 | DE10: 59.449 | DF10: 207.25 | DG10: 23 | DH10: 339.25 | DI10: 6.921 | DJ10: 1249 | DK10: 118 | DL10: 4.034 | DM10: 10 | DN10: 2910 | DO10: 11 | DP10: 221.25 | DQ10: 11.642 | DR10: 7.263 | DS10: 5.174 | DT10: 0 | DU10: 19 | DV10: 0 | DW10: 78.947 | DX10: 100 | DY10: 10 | DZ10: 45 | EA10: 7.154 | EB10: 12 | EC10: 32 | ED10: 0 | EE10: 11 | EF10: 173 | EG10: 20.625 | EH10: 52.941 | EI10: 39.815 | EJ10: 59.26 | EK10: -4
A11: 36 | B11: 16 | C11: 1 | D11: 2025 | E11: 1 | F11: =VLOOKUP(G11, Map!$A$1:$B$33, 2, FALSE) -> JAX | G11: Jaguars | H11: =VLOOKUP(I11, Map!$A$1:$B$33, 2, FALSE) -> CAR | I11: Panthers | J11: 0 | K11: 0 | L11: 0 | M11: 1 | N11: 4 | O11: 3 | P11: 22.142857 | Q11: 20.857143 | R11: -9 | S11: -2 | T11: 0.5714286 | U11: 1 | V11: 0 | W11: 3 | X11: 2 | Y11: 1 | Z11: 1 | AA11: 2 | AB11: 1 | AC11: 10 | AD11: 8 | AE11: 9 | AF11: 9 | AG11: 58 | AH11: 0 | AI11: 4 | AJ11: 4 | AK11: 24 | AL11: 19.25 | AM11: -38 | AN11: -1 | AO11: 0.5 | AP11: 1 | AQ11: 0 | AR11: 3 | AS11: 1 | AT11: 1 | AU11: 3 | AV11: 2 | AW11: 1 | AX11: 7 | AY11: 10 | AZ11: 9 | BA11: 8 | BB11: 58 | BC11: 40.5 | BD11: -10 | BE11: 0 | BF11: 0 | BG11: 60.978 | BH11: 27.239 | BI11: 38.711 | BJ11: 86.441 | BK11: 74.884 | BL11: 90.353 | BM11: 4.099 | BN11: 38.711 | BO11: 27.239 | BP11: 0 | BQ11: 60.978 | BR11: -4.099 | BS11: 25.116 | BT11: 13.559 | BU11: 9.647 | BV11: 2100 | BW11: 58.687 | BX11: 215.14285 | BY11: 21 | BZ11: 351.14285 | CA11: 6.255 | CB11: 1033 | CC11: 119.714 | CD11: 4.682 | CE11: 6 | CF11: 2695 | CG11: 9 | CH11: 231.429 | CI11: 10.658 | CJ11: 7.375 | CK11: 3.188 | CL11: 2 | CM11: 8 | CN11: 0 | CO11: 93.333 | CP11: 71.429 | CQ11: 10 | CR11: 44 | CS11: 4.429 | CT11: 30 | CU11: 10 | CV11: 12 | CW11: 9 | CX11: 146 | CY11: 19.143 | CZ11: 53.333 | DA11: 32.979 | DB11: 59.74 | DC11: 8 | DD11: 2241 | DE11: 62.452 | DF11: 179.5 | DG11: 19 | DH11: 334.5 | DI11: 6.057 | DJ11: 1145 | DK11: 136.875 | DL11: 4.64 | DM11: 4 | DN11: 2816 | DO11: 12 | DP11: 197.625 | DQ11: 9.699 | DR11: 6.846 | DS11: 4.75 | DT11: 1 | DU11: 13 | DV11: 0 | DW11: 86.667 | DX11: 86.667 | DY11: 13 | DZ11: 52 | EA11: 16.412 | EB11: 11 | EC11: 27 | ED11: 6 | EE11: 12 | EF11: 154 | EG11: 20.75 | EH11: 68.421 | EI11: 37.255 | EJ11: 70.83 | EK11: -5
A12: 32 | B12: 8 | C12: 1 | D12: 2025 | E12: 1 | F12: =VLOOKUP(G12, Map!$A$1:$B$33, 2, FALSE) -> DEN | G12: Broncos | H12: =VLOOKUP(I12, Map!$A$1:$B$33, 2, FALSE) -> TEN | I12: Titans | J12: 0 | K12: 0 | L12: 0 | M12: 1 | N12: 6 | O12: 2 | P12: 18.875 | Q12: 25.875 | R12: 56 | S12: 5 | T12: 0.75 | U12: 0 | V12: 1 | W12: 4 | X12: 0 | Y12: 2 | Z12: 2 | AA12: 3 | AB12: 2 | AC12: 4 | AD12: 12 | AE12: 7 | AF12: 9 | AG12: 63 | AH12: 0 | AI12: 1 | AJ12: 7 | AK12: 28.75 | AL12: 13.75 | AM12: -120 | AN12: -3 | AO12: 0.125 | AP12: 0 | AQ12: 3 | AR12: 0 | AS12: 3 | AT12: 1 | AU12: 4 | AV12: 0 | AW12: 6 | AX12: 7 | AY12: 9 | AZ12: 8 | BA12: 7 | BB12: 59 | BC12: 39 | BD12: -10 | BE12: 0 | BF12: 0 | BG12: 67.604 | BH12: 40.033 | BI12: 32.138 | BJ12: 97.308 | BK12: 27.746 | BL12: 67.455 | BM12: 7.676 | BN12: 32.138 | BO12: 40.033 | BP12: 0 | BQ12: 67.604 | BR12: -7.676 | BS12: 72.254 | BT12: 2.692 | BU12: 32.545 | BV12: 2703 | BW12: 62.807 | BX12: 219.125 | BY12: 22 | BZ12: 363.125 | CA12: 6.326 | CB12: 1407 | CC12: 137.75 | CD12: 5.009 | CE12: 10 | CF12: 3223 | CG12: 15 | CH12: 225.375 | CI12: 10.073 | CJ12: 6.028 | CK12: 90.5 | CL12: 0 | CM12: 36 | CN12: 0 | CO12: 100 | CP12: 90.909 | CQ12: 10 | CR12: 51 | CS12: 10.467 | CT12: 38 | CU12: 18 | CV12: 0 | CW12: 15 | CX12: 207 | CY12: 20.75 | CZ12: 50 | DA12: 37.864 | DB12: 73.02 | DC12: -1 | DD12: 1785 | DE12: 57.664 | DF12: 168.375 | DG12: 21 | DH12: 282.25 | DI12: 5.894 | DJ12: 643 | DK12: 80.375 | DL12: 3.921 | DM12: 3 | DN12: 2580 | DO12: 5 | DP12: 201.875 | DQ12: 10.222 | DR12: 6.813 | DS12: 4.895 | DT12: 0 | DU12: 16 | DV12: 0 | DW12: 88.889 | DX12: 76.19 | DY12: 16 | DZ12: 56 | EA12: 10.75 | EB12: 12 | EC12: 37 | ED12: 6 | EE12: 5 | EF12: 110 | EG12: 15.875 | EH12: 38.462 | EI12: 29.907 | EJ12: 65.31 | EK12: -4
A13: 30 | B13: -4 | C13: 0 | D13: 2025 | E13: 1 | F13: =VLOOKUP(G13, Map!$A$1:$B$33, 2, FALSE) -> SEA | G13: Seahawks | H13: =VLOOKUP(I13, Map!$A$1:$B$33, 2, FALSE) -> SF | I13: 49ers | J13: 0 | K13: 0 | L13: 0 | M13: 0 | N13: 5 | O13: 2 | P13: 19.428572 | Q13: 27.571428 | R13: 57 | S13: 2 | T13: 0.71428573 | U13: 1 | V13: 1 | W13: 2 | X13: 2 | Y13: 3 | Z13: 0 | AA13: 2 | AB13: 2 | AC13: 9 | AD13: 8 | AE13: 7 | AF13: 10 | AG13: 61 | AH13: 1 | AI13: 5 | AJ13: 3 | AK13: 20.5 | AL13: 20 | AM13: -4 | AN13: -1 | AO13: 0.625 | AP13: 3 | AQ13: 0 | AR13: 2 | AS13: 1 | AT13: 3 | AU13: 2 | AV13: 5 | AW13: 1 | AX13: 15 | AY13: 5 | AZ13: 13 | BA13: 7 | BB13: 68 | BC13: 36 | BD13: -0.5 | BE13: 0 | BF13: 0 | BG13: 44.621 | BH13: 51.069 | BI13: 55.021 | BJ13: 42.511 | BK13: 23.279 | BL13: 42.594 | BM13: -1.696 | BN13: 55.021 | BO13: 51.069 | BP13: 0 | BQ13: 44.621 | BR13: 1.696 | BS13: 76.721 | BT13: 57.489 | BU13: 57.406 | BV13: 2459 | BW13: 67.857 | BX13: 244.42857 | BY13: 27 | BZ13: 358.85715 | CA13: 9.026 | CB13: 918 | CC13: 106.143 | CD13: 3.678 | CE13: 8 | CF13: 2854 | CG13: 12 | CH13: 252.714 | CI13: 13.301 | CJ13: 7.174 | CK13: 7.889 | CL13: 2 | CM13: 23 | CN13: 0 | CO13: 100 | CP13: 76.471 | CQ13: 13 | CR13: 61 | CS13: 11 | CT13: 26 | CU13: 10 | CV13: 6 | CW13: 12 | CX13: 193 | CY13: 19.429 | CZ13: 66.667 | DA13: 33.333 | DB13: 76.57 | DC13: -4 | DD13: 2753 | DE13: 65.886 | DF13: 259.25 | DG13: 23 | DH13: 362.25 | DI13: 7.301 | DJ13: 775 | DK13: 89.375 | DL13: 3.405 | DM13: 3 | DN13: 3588 | DO13: 12 | DP13: 272.875 | DQ13: 11.081 | DR13: 6.667 | DS13: 1.889 | DT13: 0 | DU13: 9 | DV13: 0 | DW13: 92.308 | DX13: 90 | DY13: 18 | DZ13: 66 | EA13: 14.308 | EB13: 12 | EC13: 25 | ED13: 0 | EE13: 12 | EF13: 160 | EG13: 20.875 | EH13: 54.545 | EI13: 46.364 | EJ13: 65.71 | EK13: -5
... A273: 0 | B273: 0 | C273: 0 | D273: 2025 | E273: 18 | F273: =VLOOKUP(G273, Map!$A$1:$B$33, 2, FALSE) -> HOU | G273: Texans | H273: =VLOOKUP(I273, Map!$A$1:$B$33, 2, FALSE) -> IND | I273: Colts | J273: 0 | K273: 0 | L273: 0 | M273: 0 | N273: 3 | O273: 4 | P273: 14.714286 | Q273: 21.857143 | R273: 50 | S273: 1 | T273: 0.42857143 | U273: 1 | V273: 1 | W273: 2 | X273: 1 | Y273: 1 | Z273: 3 | AA273: 2 | AB273: 1 | AC273: 3 | AD273: 13 | AE273: 8 | AF273: 8 | AG273: 69 | AH273: 0 | AI273: 7 | AJ273: 1 | AK273: 19.25 | AL273: 33.75 | AM273: 116 | AN273: 4 | AO273: 0.875 | AP273: 2 | AQ273: 0 | AR273: 5 | AS273: 0 | AT273: 2 | AU273: 1 | AV273: 6 | AW273: 0 | AX273: 4 | AY273: 12 | AZ273: 6 | BA273: 11 | BB273: 68 | BC273: 0 | BD273: 0 | BE273: 0 | BF273: 0 | BG273: 46.071 | BH273: 73.628 | BI273: 53.559 | BJ273: 0 | BK273: 0 | BL273: 0 | BM273: -1.565 | BN273: 53.559 | BO273: 73.628 | BP273: 0 | BQ273: 46.071 | BR273: 1.565 | BS273: 0 | BT273: 0 | BU273: 0 | BV273: 2266 | BW273: 66.525 | BX273: 215.28572 | BY273: 22 | BZ273: 348.57144 | CA273: 6.975 | CB273: 869 | CC273: 113.429 | CD273: 4.269 | CE273: 3 | CF273: 2816 | CG273: 11 | CH273: 235.143 | CI273: 10.484 | CJ273: 7.875 | CK273: 6.111 | CL273: 1 | CM273: 16 | CN273: 0 | CO273: 100 | CP273: 89.474 | CQ273: 17 | CR273: 63 | CS273: 11.545 | CT273: 27 | CU273: 9 | CV273: 6 | CW273: 11 | CX273: 153 | CY273: 18.714 | CZ273: 66.667 | DA273: 35.165 | DB273: 60.15 | DC273: 4 | DD273: 2891 | DE273: 70.161 | DF273: 250.875 | DG273: 23 | DH273: 393.25 | DI273: 8.351 | DJ273: 1690 | DK273: 134.375 | DL273: 5.023 | DM273: 18 | DN273: 3396 | DO273: 13 | DP273: 258.875 | DQ273: 11.902 | DR273: 6.826 | DS273: 6.091 | DT273: 1 | DU273: 23 | DV273: 0 | DW273: 96.296 | DX273: 94.118 | DY273: 16 | DZ273: 74 | EA273: 4.25 | EB273: 8 | EC273: 16 | ED273: 6 | EE273: 13 | EF273: 270 | EG273: 23.25 | EH273: 83.333 | EI273: 45.349 | EJ273: 77.07 | EK273: 8

Sheet Map
A1: Team Name | B1: Abbreviation
A2: Cardinals | B2: ARI
A3: Falcons | B3: ATL
A4: Ravens | B4: BAL
A5: Bills | B5: BUF
A6: Panthers | B6: CAR
A7: Bears | B7: CHI
A8: Bengals | B8: CIN
A9: Browns | B9: CLE
A10: Cowboys | B10: DAL
A11: Broncos | B11: DEN
A12: Lions | B12: DET
... A33: Commanders | B33: WAS

Sheet Range_2018_2024
A1: TotalPoints | B1: Spread | C1: HomeWin | D1: season | E1: week | F1: team | G1: HomeTeamName | H1: opponent_team | I1: AwayTeamName | J1: HomeTeamId | K1: AwayTeamId | L1: HomeWinner | M1: AwayWinner | N1: AveragePredictedTotal | O1: AveragePredictedSpread | P1: BestPredictedTotal | Q1: BestPredictedSpread | R1: MeanTemperature | S1: MaxTemperature | T1: MinTemperature | U1: ApparentTemperature | V1: PrecipitationSum | W1: SnowfallSum | X1: PrecipitationHours | Y1: RainSum | Z1: WindSpeedMax | AA1: WindGustsMax | AB1: DominantWindDirection | AC1: MeanRelativeHumidity | AD1: MeanWindGusts | AE1: MeanWindSpeed | AF1: PredictedHomeWinPercent | AG1: PredicitedHomeMatchupQuality | AH1: PredictedHomeLossPercent | AI1: PredictedHomeDefenseEfficiency | AJ1: PredictedHomeOffenseEfficiency | AK1: PredictedHomeTotalEfficiency | AL1: PredictedHomePointDifferential | AM1: PredictedAwayWinPercent | AN1: PredicitedAwayMatchupQuality | AO1: PredictedAwayLossPercent | AP1: PredictedAwayPointDifferential | AQ1: PredictedAwayDefenseEfficiency | AR1: PredictedAwayOffenseEfficiency | AS1: PredictedAwayTotalEfficiency
A2: 47 | B2: 1 | C2: 1 | D2: 2018 | E2: 1 | F2: =H2 -> CHI | G2: Packers | H2: =IFERROR(VLOOKUP(I2, Map!$A$1:$B$33, 2, FALSE),"WAS") -> CHI | I2: Bears | J2: 9 | K2: 3 | L2: 1 | M2: 0 | N2: 41.583333 | O2: -6.25 | P2: -6.5 | Q2: 45 | R2: 15.4 | S2: 21 | T2: 10.7 | U2: 15 | V2: 0 | W2: 0 | X2: 0 | Y2: 0 | Z2: 11.2 | AA2: 24.8 | AB2: 42 | AC2: 77 | AD2: 14.2 | AE2: 6.1 | AF2: 73.1 | AG2: 77.434 | AH2: 26.7 | AI2: 51 | AJ2: 25.837 | AK2: 34.597 | AL2: 8.871 | AM2: 26.7 | AN2: 77.434 | AO2: 73.1 | AP2: -8.871 | AQ2: 74.163 | AR2: 49 | AS2: 65.403
A3: 40 | B3: 8 | C3: 1 | D3: 2018 | E3: 1 | F3: =IFERROR(VLOOKUP(G3, Map!$A$1:$B$33, 2, FALSE),"WAS") -> MIN | G3: Vikings | H3: =IFERROR(VLOOKUP(I3, Map!$A$1:$B$33, 2, FALSE),"WAS") -> SF | I3: 49ers | J3: 16 | K3: 25 | L3: 1 | M3: 0 | N3: 42.125 | O3: -5.9166667 | P3: -6 | Q3: 44.5 | R3: 15.9 | S3: 21.1 | T3: 11.4 | U3: 14.5 | V3: 0 | W3: 0 | X3: 0 | Y3: 0 | Z3: 15.1 | AA3: 32 | AB3: 138 | AC3: 71 | AD3: 21.5 | AE3: 10.9 | AF3: 69.7 | AG3: 48.903 | AH3: 30 | AI3: 93.84 | AJ3: 42.065 | AK3: 81.007 | AL3: 7.442 | AM3: 30 | AN3: 48.903 | AO3: 69.7 | AP3: -7.442 | AQ3: 57.935 | AR3: 6.16 | AS3: 18.993
A4: 30 | B4: 6 | C4: 1 | D4: 2018 | E4: 1 | F4: =IFERROR(VLOOKUP(G4, Map!$A$1:$B$33, 2, FALSE),"WAS") -> PHI | G4: Eagles | H4: =IFERROR(VLOOKUP(I4, Map!$A$1:$B$33, 2, FALSE),"WAS") -> ATL | I4: Falcons | J4: 21 | K4: 1 | L4: 1 | M4: 0 | N4: 40.583333 | O4: 0.25 | P4: 1 | Q4: 44 | R4: 25.1 | S4: 28.9 | T4: 22.9 | U4: 28.6 | V4: 9.5 | W4: 0 | X4: 8 | Y4: 9.5 | Z4: 11.2 | AA4: 25.2 | AB4: 23 | AC4: 82 | AD4: 17.5 | AE4: 8.5 | AF4: 58.6 | AG4: 69.084 | AH4: 41.1 | AI4: 84.526 | AJ4: 40.233 | AK4: 61.075 | AL4: 3.176 | AM4: 41.1 | AN4: 69.084 | AO4: 58.6 | AP4: -3.176 | AQ4: 59.767 | AR4: 15.474 | AS4: 38.925
A5: 47 | B5: 7 | C5: 1 | D5: 2018 | E5: 1 | F5: =IFERROR(VLOOKUP(G5, Map!$A$1:$B$33, 2, FALSE),"WAS") -> NE | G5: Patriots | H5: =IFERROR(VLOOKUP(I5, Map!$A$1:$B$33, 2, FALSE),"WAS") -> HOU | I5: Texans | J5: 17 | K5: 34 | L5: 1 | M5: 0 | N5: 45.083333 | O5: -5.7083333 | P5: -6 | Q5: 45.5 | R5: 14.8 | S5: 16.9 | T5: 12.9 | U5: 12.2 | V5: 0.1 | W5: 0 | X5: 1 | Y5: 0.1 | Z5: 17.3 | AA5: 41.8 | AB5: 26 | AC5: 60 | AD5: 29.7 | AE5: 12.8 | AF5: 72.6 | AG5: 72.971 | AH5: 27.1 | AI5: 92.761 | AJ5: 58.187 | AK5: 80.422 | AL5: 8.667 | AM5: 27.1 | AN5: 72.971 | AO5: 72.6 | AP5: -8.667 | AQ5: 41.813 | AR5: 7.239 | AS5: 19.578
A6: 66 | B6: -10 | C6: 0 | D6: 2018 | E6: 1 | F6: =IFERROR(VLOOKUP(G6, Map!$A$1:$B$33, 2, FALSE),"WAS") -> LAC | G6: Chargers | H6: =IFERROR(VLOOKUP(I6, Map!$A$1:$B$33, 2, FALSE),"WAS") -> KC | I6: Chiefs | J6: 24 | K6: 12 | L6: 0 | M6: 0 | N6: 45.458333 | O6: -2.125 | P6: -3.5 | Q6: 47.5 | R6: 22.9 | S6: 31.5 | T6: 17.7 | U6: 24.9 | V6: 0 | W6: 0 | X6: 0 | Y6: 0 | Z6: 17.6 | AA6: 36 | AB6: 226 | AC6: 77 | AD6: 17.6 | AE6: 7.8 | AF6: 62.4 | AG6: 93.737 | AH6: 37.3 | AI6: 14.156 | AJ6: 71.46 | AK6: 13.898 | AL6: 4.569 | AM6: 37.3 | AN6: 93.737 | AO6: 62.4 | AP6: -4.569 | AQ6: 28.54 | AR6: 85.844 | AS6: 86.102
A7: 35 | B7: -5 | C7: 0 | D7: 2018 | E7: 1 | F7: =IFERROR(VLOOKUP(G7, Map!$A$1:$B$33, 2, FALSE),"WAS") -> NYG | G7: Giants | H7: =IFERROR(VLOOKUP(I7, Map!$A$1:$B$33, 2, FALSE),"WAS") -> JAX | I7: Jaguars | J7: 19 | K7: 30 | L7: 0 | M7: 0 | N7: 38.75 | O7: 2.875 | P7: 2.5 | Q7: 40.5 | R7: 14.8 | S7: 16.6 | T7: 13.1 | U7: 13.3 | V7: 14.4 | W7: 0 | X7: 24 | Y7: 14.4 | Z7: 16.1 | AA7: 33.1 | AB7: 33 | AC7: 84 | AD7: 28.8 | AE7: 14.7 | AF7: 51 | AG7: 38.121 | AH7: 48.7 | AI7: 72.279 | AJ7: 10.902 | AK7: 32.557 | AL7: 0.414 | AM7: 48.7 | AN7: 38.121 | AO7: 51 | AP7: -0.414 | AQ7: 89.098 | AR7: 27.721 | AS7: 67.443
A8: 30 | B8: -18 | C8: 0 | D8: 2018 | E8: 1 | F8: =IFERROR(VLOOKUP(G8, Map!$A$1:$B$33, 2, FALSE),"WAS") -> ARI | G8: Cardinals | H8: =IFERROR(VLOOKUP(I8, Map!$A$1:$B$33, 2, FALSE),"WAS") -> WAS | I8: Redskins | J8: 22 | K8: 28 | L8: 0 | M8: 0 | N8: 38.916667 | O8: -0.41666667 | P8: -2 | Q8: 31.5 | R8: 25.2 | S8: 34.4 | T8: 18 | U8: 26.7 | V8: 0 | W8: 0 | X8: 0 | Y8: 0 | Z8: 12.6 | AA8: 31.7 | AB8: 161 | AC8: 60 | AD8: 15.7 | AE8: 6 | AF8: 57.3 | AG8: 2.67 | AH8: 42.3 | AI8: 11.514 | AJ8: 13.761 | AK8: 6.171 | AL8: 2.708 | AM8: 42.3 | AN8: 2.67 | AO8: 57.3 | AP8: -2.708 | AQ8: 86.239 | AR8: 88.486 | AS8: 93.829
A9: 88 | B9: -8 | C9: 0 | D9: 2018 | E9: 1 | F9: =IFERROR(VLOOKUP(G9, Map!$A$1:$B$33, 2, FALSE),"WAS") -> NO | G9: Saints | H9: =IFERROR(VLOOKUP(I9, Map!$A$1:$B$33, 2, FALSE),"WAS") -> TB | I9: Buccaneers | J9: 18 | K9: 27 | L9: 0 | M9: 0 | N9: 48.625 | O9: -8.25 | P9: 0.5 | Q9: 49.5 | R9: 26.5 | S9: 29.4 | T9: 24.2 | U9: 32 | V9: 3.4 | W9: 0 | X9: 11 | Y9: 3.4 | Z9: 8.5 | AA9: 21.2 | AB9: 190 | AC9: 88 | AD9: 14.1 | AE9: 5.5 | AF9: 81.9 | AG9: 52.67 | AH9: 17.9 | AI9: 1.29 | AJ9: 74.815 | AK9: 15.385 | AL9: 13.117 | AM9: 17.9 | AN9: 52.67 | AO9: 81.9 | AP9: -13.117 | AQ9: 25.185 | AR9: 98.71 | AS9: 84.615
A10: 24 | B10: 8 | C10: 1 | D10: 2018 | E10: 1 | F10: =IFERROR(VLOOKUP(G10, Map!$A$1:$B$33, 2, FALSE),"WAS") -> CAR | G10: Panthers | H10: =IFERROR(VLOOKUP(I10, Map!$A$1:$B$33, 2, FALSE),"WAS") -> DAL | I10: Cowboys | J10: 29 | K10: 6 | L10: 1 | M10: 0 | N10: 37.458333 | O10: -3 | P10: -2.5 | Q10: 29.5 | R10: 26.2 | S10: 29.2 | T10: 22.4 | U10: 29.1 | V10: 3.4 | W10: 0 | X10: 11 | Y10: 3.4 | Z10: 11.8 | AA10: 28.4 | AB10: 146 | AC10: 70 | AD10: 18 | AE10: 7.1 | AF10: 59.9 | AG10: 66.324 | AH10: 39.8 | AI10: 84.099 | AJ10: 39.161 | AK10: 79.22 | AL10: 3.647 | AM10: 39.8 | AN10: 66.324 | AO10: 59.9 | AP10: -3.647 | AQ10: 60.839 | AR10: 15.901 | AS10: 20.78
A11: 51 | B11: 3 | C11: 1 | D11: 2018 | E11: 1 | F11: =IFERROR(VLOOKUP(G11, Map!$A$1:$B$33, 2, FALSE),"WAS") -> DEN | G11: Broncos | H11: =IFERROR(VLOOKUP(I11, Map!$A$1:$B$33, 2, FALSE),"WAS") -> SEA | I11: Seahawks | J11: 7 | K11: 26 | L11: 1 | M11: 0 | N11: 40.25 | O11: -2.9583333 | P11: -3 | Q11: 42.5 | R11: 20.5 | S11: 28.7 | T11: 12.1 | U11: 18.7 | V11: 0 | W11: 0 | X11: 0 | Y11: 0 | Z11: 23.9 | AA11: 39.6 | AB11: 295 | AC11: 46 | AD11: 21 | AE11: 9.1 | AF11: 54.6 | AG11: 65.009 | AH11: 45 | AI11: 72.758 | AJ11: 41.936 | AK11: 59.525 | AL11: 1.719 | AM11: 45 | AN11: 65.009 | AO11: 54.6 | AP11: -1.719 | AQ11: 58.064 | AR11: 27.242 | AS11: 40.475
A12: 50 | B12: 44 | C12: 1 | D12: 2018 | E12: 1 | F12: =IFERROR(VLOOKUP(G12, Map!$A$1:$B$33, 2, FALSE),"WAS") -> BAL | G12: Ravens | H12: =IFERROR(VLOOKUP(I12, Map!$A$1:$B$33, 2, FALSE),"WAS") -> BUF | I12: Bills | J12: 33 | K12: 2 | L12: 1 | M12: 0 | N12: 35.791667 | O12: -7.125 | P12: -7.5 | Q12: 38.5 | R12: 16.8 | S12: 19 | T12: 15.3 | U12: 15.1 | V12: 42.2 | W12: 0 | X12: 24 | Y12: 42.2 | Z12: 30.9 | AA12: 54.7 | AB12: 54 | AC12: 91 | AD12: 42.6 | AE12: 23.9 | AF12: 83.7 | AG12: 51.452 | AH12: 16.2 | AI12: 99.727 | AJ12: 69.325 | AK12: 98.78 | AL12: 14.122 | AM12: 16.2 | AN12: 51.452 | AO12: 83.7 | AP12: -14.122 | AQ12: 30.675 | AR12: 0.273 | AS12: 1.22
A13: 46 | B13: -20 | C13: 0 | D13: 2018 | E13: 1 | F13: =IFERROR(VLOOKUP(G13, Map!$A$1:$B$33, 2, FALSE),"WAS") -> LV | G13: Raiders | H13: =IFERROR(VLOOKUP(I13, Map!$A$1:$B$33, 2, FALSE),"WAS") -> LA | I13: Rams | J13: 13 | K13: 14 | L13: 0 | M13: 0 | N13: 43.416667 | O13: 5.75 | P13: 6 | Q13: 46.5 | R13: 17.5 | S13: 21.8 | T13: 13.7 | U13: 16 | V13: 0 | W13: 0 | X13: 0 | Y13: 0 | Z13: 30.3 | AA13: 51.1 | AB13: 255 | AC13: 68 | AD13: 27.4 | AE13: 15.6 | AF13: 42.7 | AG13: 49.699 | AH13: 56.9 | AI13: 15.382 | AJ13: 26.95 | AK13: 19.929 | AL13: -2.566 | AM13: 56.9 | AN13: 49.699 | AO13: 42.7 | AP13: 2.566 | AQ13: 73.05 | AR13: 84.618 | AS13: 80.071
A14: 57 | B14: -11 | C14: 0 | D14: 2018 | E14: 1 | F14: =IFERROR(VLOOKUP(G14, Map!$A$1:$B$33, 2, FALSE),"WAS") -> IND | G14: Colts | H14: =IFERROR(VLOOKUP(I14, Map!$A$1:$B$33, 2, FALSE),"WAS") -> CIN | I14: Bengals | J14: 11 | K14: 4 | L14: 0 | M14: 0 | N14: 44.125 | O14: 0.33333333 | P14: -1 | Q14: 47.5 | R14: 15.6 | S14: 17.7 | T14: 14.2 | U14: 13.6 | V14: 21.1 | W14: 0 | X14: 21 | Y14: 21.1 | Z14: 26.5 | AA14: 62.3 | AB14: 46 | AC14: 86 | AD14: 42.4 | AE14: 21.1 | AF14: 61.4 | AG14: 51.689 | AH14: 38.3 | AI14: 39.501 | AJ14: 38.135 | AK14: 33.296 | AL14: 4.21 | AM14: 38.3 | AN14: 51.689 | AO14: 61.4 | AP14: -4.21 | AQ14: 61.865 | AR14: 60.499 | AS14: 66.704
... A264: 36 | B264: 30 | C264: 1 | D264: 2019 | E264: 1 | F264: =IFERROR(VLOOKUP(G264, Map!$A$1:$B$33, 2, FALSE),"WAS") -> NE | G264: Patriots | H264: =IFERROR(VLOOKUP(I264, Map!$A$1:$B$33, 2, FALSE),"WAS") -> PIT | I264: Steelers | J264: 17 | K264: 23 | L264: 1 | M264: 0 | N264: 41.291667 | O264: -4.5833333 | P264: -5.5 | Q264: 40 | R264: 17.2 | S264: 22.4 | T264: 12.1 | U264: 16.6 | V264: 0 | W264: 0 | X264: 0 | Y264: 0 | Z264: 11.8 | AA264: 30.2 | AB264: 18 | AC264: 70 | AD264: 18.4 | AE264: 7.6 | AF264: 65.062 | AG264: 59.969 | AH264: 34.659 | AI264: 89.762 | AJ264: 89.915 | AK264: 96.559 | AL264: 5.62 | AM264: 34.659 | AN264: 59.969 | AO264: 65.062 | AP264: -5.62 | AQ264: 10.085 | AR264: 10.238 | AS264: 3.441
A265: 59 | B265: 5 | C265: 1 | D265: 2019 | E265: 1 | F265: =IFERROR(VLOOKUP(G265, Map!$A$1:$B$33, 2, FALSE),"WAS") -> PHI | G265: Eagles | H265: =IFERROR(VLOOKUP(I265, Map!$A$1:$B$33, 2, FALSE),"WAS") -> WAS | J265: 21 | K265: 28 | L265: 1 | M265: 0 | N265: 39.625 | O265: -8.625 | P265: -10 | Q265: 43 | R265: 21.1 | S265: 27.9 | T265: 15.2 | U265: 21.1 | V265: 0 | W265: 0 | X265: 0 | Y265: 0 | Z265: 13.6 | AA265: 27 | AB265: 274 | AC265: 62 | AD265: 17.1 | AE265: 7.8 | AF265: 77.88 | AG265: 40.281 | AH265: 21.944 | AI265: 31.279 | AJ265: 88.226 | AK265: 72.044 | AL265: 11.089 | AM265: 21.944 | AN265: 40.281 | AO265: 77.88 | AP265: -11.089 | AQ265: 11.774 | AR265: 68.721 | AS265: 27.956
A266: 52 | B266: 18 | C266: 1 | D266: 2019 | E266: 1 | F266: =IFERROR(VLOOKUP(G266, Map!$A$1:$B$33, 2, FALSE),"WAS") -> DAL | G266: Cowboys | H266: =IFERROR(VLOOKUP(I266, Map!$A$1:$B$33, 2, FALSE),"WAS") -> NYG | I266: Giants | J266: 6 | K266: 19 | L266: 1 | M266: 0 | N266: 39.541667 | O266: -5.9166667 | P266: -6.5 | Q266: 44 | R266: 31.2 | S266: 36.6 | T266: 25.3 | U266: 31.3 | V266: 0 | W266: 0 | X266: 0 | Y266: 0 | Z266: 23.3 | AA266: 42.1 | AB266: 190 | AC266: 42 | AD266: 29.1 | AE266: 16 | AF266: 75.325 | AG266: 49.567 | AH266: 24.478 | AI266: 35.204 | AJ266: 97.865 | AK266: 91.079 | AL266: 9.892 | AM266: 24.478 | AN266: 49.567 | AO266: 75.325 | AP266: -9.892 | AQ266: 2.135 | AR266: 64.796 | AS266: 8.921
A267: 56 | B267: -30 | C267: 0 | D267: 2019 | E267: 1 | F267: =IFERROR(VLOOKUP(G267, Map!$A$1:$B$33, 2, FALSE),"WAS") -> CLE | G267: Browns | H267: =IFERROR(VLOOKUP(I267, Map!$A$1:$B$33, 2, FALSE),"WAS") -> TEN | I267: Titans | J267: 5 | K267: 10 | L267: 0 | M267: 0 | N267: 39.083333 | O267: -5.0416667 | P267: -5.5 | Q267: 19.5 | R267: 18.8 | S267: 20.2 | T267: 17.3 | U267: 18.8 | V267: 0.4 | W267: 0 | X267: 3 | Y267: 0.4 | Z267: 18.1 | AA267: 32.4 | AB267: 10 | AC267: 77 | AD267: 21.4 | AE267: 11.7 | AF267: 56.607 | AG267: 65.377 | AH267: 43.048 | AI267: 25.34 | AJ267: 19.327 | AK267: 14.121 | AL267: 2.456 | AM267: 43.048 | AN267: 65.377 | AO267: 56.607 | AP267: -2.456 | AQ267: 80.673 | AR267: 74.66 | AS267: 85.879
A268: 58 | B268: 2 | C268: 1 | D268: 2019 | E268: 1 | F268: =IFERROR(VLOOKUP(G268, Map!$A$1:$B$33, 2, FALSE),"WAS") -> NO | G268: Saints | H268: =IFERROR(VLOOKUP(I268, Map!$A$1:$B$33, 2, FALSE),"WAS") -> HOU | I268: Texans | J268: 18 | K268: 34 | L268: 1 | M268: 0 | N268: 44.846154 | O268: -6.1153846 | P268: -6.5 | Q268: 20.5 | R268: 29.1 | S268: 32.4 | T268: 26.4 | U268: 35 | V268: 0.4 | W268: 0 | X268: 3 | Y268: 0.4 | Z268: 12.3 | AA268: 21.2 | AB268: 232 | AC268: 79 | AD268: 12.3 | AE268: 5.7 | AF268: 65.292 | AG268: 74.341 | AH268: 34.431 | AI268: 11.731 | AJ268: 87.859 | AK268: 50.418 | AL268: 5.709 | AM268: 34.431 | AN268: 74.341 | AO268: 65.292 | AP268: -5.709 | AQ268: 12.141 | AR268: 88.269 | AS268: 49.582
A269: 66 | B269: -14 | C269: 0 | D269: 2019 | E269: 1 | F269: =IFERROR(VLOOKUP(G269, Map!$A$1:$B$33, 2, FALSE),"WAS") -> JAX | G269: Jaguars | H269: =IFERROR(VLOOKUP(I269, Map!$A$1:$B$33, 2, FALSE),"WAS") -> KC | I269: Chiefs | J269: 30 | K269: 12 | L269: 0 | M269: 0 | N269: 45.375 | O269: 2.9166667 | P269: 3.5 | Q269: 49 | R269: 27.5 | S269: 33.8 | T269: 22.2 | U269: 31.9 | V269: 0 | W269: 0 | X269: 0 | Y269: 0 | Z269: 16.3 | AA269: 30.2 | AB269: 174 | AC269: 77 | AD269: 16.6 | AE269: 8.5 | AF269: 41.449 | AG269: 72.798 | AH269: 58.218 | AI269: 1.881 | AJ269: 56.705 | AK269: 8.461 | AL269: -3.045 | AM269: 58.218 | AN269: 72.798 | AO269: 41.449 | AP269: 3.045 | AQ269: 43.295 | AR269: 98.119 | AS269: 91.539
A270: 40 | B270: 16 | C270: 1 | D270: 2019 | E270: 1 | F270: =IFERROR(VLOOKUP(G270, Map!$A$1:$B$33, 2, FALSE),"WAS") -> MIN | G270: Vikings | H270: =IFERROR(VLOOKUP(I270, Map!$A$1:$B$33, 2, FALSE),"WAS") -> ATL | I270: Falcons | J270: 16 | K270: 1 | L270: 1 | M270: 0 | N270: 39.833333 | O270: -2.9166667 | P270: -3.5 | Q270: 39.5 | R270: 13.8 | S270: 16.8 | T270: 11.6 | U270: 12.5 | V270: 4.3 | W270: 0 | X270: 12 | Y270: 4.3 | Z270: 15.2 | AA270: 31.7 | AB270: 73 | AC270: 81 | AD270: 20.2 | AE270: 10.7 | AF270: 59.195 | AG270: 67.646 | AH270: 40.48 | AI270: 85.257 | AJ270: 92.187 | AK270: 96.86 | AL270: 3.405 | AM270: 40.48 | AN270: 67.646 | AO270: 59.195 | AP270: -3.405 | AQ270: 7.813 | AR270: 14.743 | AS270: 3.14
A271: 41 | B271: 1 | C271: 1 | D271: 2019 | E271: 1 | F271: =IFERROR(VLOOKUP(G271, Map!$A$1:$B$33, 2, FALSE),"WAS") -> SEA | G271: Seahawks | H271: =IFERROR(VLOOKUP(I271, Map!$A$1:$B$33, 2, FALSE),"WAS") -> CIN | I271: Bengals | J271: 26 | K271: 4 | L271: 1 | M271: 0 | N271: 41.041667 | O271: -7.7083333 | P271: -8.5 | Q271: 42.5 | R271: 16.8 | S271: 19.9 | T271: 15.2 | U271: 15.9 | V271: 8.2 | W271: 0 | X271: 18 | Y271: 8.2 | Z271: 21.3 | AA271: 42.8 | AB271: 194 | AC271: 87 | AD271: 31.8 | AE271: 16.6 | AF271: 77.048 | AG271: 46.48 | AH271: 22.769 | AI271: 53.511 | AJ271: 32.589 | AK271: 52.605 | AL271: 10.691 | AM271: 22.769 | AN271: 46.48 | AO271: 77.048 | AP271: -10.691 | AQ271: 67.411 | AR271: 46.489 | AS271: 47.395
A272: 69 | B272: -49 | C272: 0 | D272: 2019 | E272: 1 | F272: =IFERROR(VLOOKUP(G272, Map!$A$1:$B$33, 2, FALSE),"WAS") -> MIA | G272: Dolphins | H272: =IFERROR(VLOOKUP(I272, Map!$A$1:$B$33, 2, FALSE),"WAS") -> BAL | I272: Ravens | J272: 15 | K272: 33 | L272: 0 | M272: 0 | N272: 39.375 | O272: 5.625 | P272: 6.5 | Q272: 40.5 | R272: 28.2 | S272: 32.1 | T272: 23.8 | U272: 33.3 | V272: 1.7 | W272: 0 | X272: 10 | Y272: 1.7 | Z272: 11.6 | AA272: 22.7 | AB272: 179 | AC272: 78 | AD272: 16.1 | AE272: 7.7 | AF272: 36.561 | AG272: 49.701 | AH272: 63.146 | AI272: 0.114 | AJ272: 5.785 | AK272: 0.049 | AL272: -4.884 | AM272: 63.146 | AN272: 49.701 | AO272: 36.561 | AP272: 4.884 | AQ272: 94.215 | AR272: 99.886 | AS272: 99.951
A273: 54 | B273: 6 | C273: 1 | D273: 2019 | E273: 1 | F273: =IFERROR(VLOOKUP(G273, Map!$A$1:$B$33, 2, FALSE),"WAS") -> LAC | G273: Chargers | H273: =IFERROR(VLOOKUP(I273, Map!$A$1:$B$33, 2, FALSE),"WAS") -> IND | I273: Colts | J273: 24 | K273: 11 | L273: 1 | M273: 0 | N273: 38.538462 | O273: -4.6538462 | P273: -4.5 | Q273: -1 | R273: 21.7 | S273: 26.9 | T273: 17.1 | U273: 21.9 | V273: 0 | W273: 0 | X273: 0 | Y273: 0 | Z273: 23.8 | AA273: 46.1 | AB273: 225 | AC273: 68 | AD273: 23.6 | AE273: 11.9 | AF273: 67.849 | AG273: 52.893 | AH273: 31.894 | AI273: 23.388 | AJ273: 88.594 | AK273: 79.944 | AL273: 6.717 | AM273: 31.894 | AN273: 52.893 | AO273: 67.849 | AP273: -6.717 | AQ273: 11.406 | AR273: 76.612 | AS273: 20.056
A274: 58 | B274: -24 | C274: 0 | D274: 2019 | E274: 2 | F274: =IFERROR(VLOOKUP(G274, Map!$A$1:$B$33, 2, FALSE),"WAS") -> CIN | G274: Bengals | H274: =IFERROR(VLOOKUP(I274, Map!$A$1:$B$33, 2, FALSE),"WAS") -> SF | I274: 49ers | J274: 4 | K274: 25 | L274: 0 | M274: 0 | N274: 38.730769 | O274: -0.73076923 | P274: 0 | Q274: -1 | R274: 22.7 | S274: 30.5 | T274: 16.8 | U274: 22.6 | V274: 0 | W274: 0 | X274: 0 | Y274: 0 | Z274: 10.8 | AA274: 27 | AB274: 182 | AC274: 57 | AD274: 14.8 | AE274: 7.1 | AF274: 44.669 | AG274: 48.374 | AH274: 54.972 | AI274: 4.029 | AJ274: 33.241 | AK274: 6.331 | AL274: -1.832 | AM274: 54.972 | AN274: 48.374 | AO274: 44.669 | AP274: 1.832 | AQ274: 66.759 | AR274: 95.971 | AS274: 93.669
A275: 37 | B275: 5 | C275: 1 | D275: 2019 | E275: 2 | F275: =IFERROR(VLOOKUP(G275, Map!$A$1:$B$33, 2, FALSE),"WAS") -> GB | G275: Packers | H275: =IFERROR(VLOOKUP(I275, Map!$A$1:$B$33, 2, FALSE),"WAS") -> MIN | I275: Vikings | J275: 9 | K275: 16 | L275: 1 | M275: 0 | N275: 36.571429 | O275: -2.5714286 | P275: -2.5 | Q275: -1 | R275: 20.1 | S275: 24.8 | T275: 16.8 | U275: 21.3 | V275: 1.6 | W275: 0 | X275: 5 | Y275: 1.6 | Z275: 12.7 | AA275: 27 | AB275: 188 | AC275: 81 | AD275: 18.7 | AE275: 7.6 | AF275: 54.94 | AG275: 83.975 | AH275: 44.701 | AI275: 83.477 | AJ275: 30.789 | AK275: 69.531 | AL275: 1.821 | AM275: 44.701 | AN275: 83.975 | AO275: 54.94 | AP275: -1.821 | AQ275: 69.211 | AR275: 16.523 | AS275: 30.469
A276: 38 | B276: -18 | C276: 0 | D276: 2019 | E276: 2 | F276: =IFERROR(VLOOKUP(G276, Map!$A$1:$B$33, 2, FALSE),"WAS") -> LV | G276: Raiders | H276: =IFERROR(VLOOKUP(I276, Map!$A$1:$B$33, 2, FALSE),"WAS") -> KC | I276: Chiefs | J276: 13 | K276: 12 | L276: 0 | M276: 0 | N276: 46.769231 | O276: 5.8076923 | P276: 6.5 | Q276: 46.5 | R276: 16.5 | S276: 18.7 | T276: 14.8 | U276: 14.4 | V276: 0 | W276: 0 | X276: 0 | Y276: 0 | Z276: 36.1 | AA276: 59.8 | AB276: 252 | AC276: 83 | AD276: 39.2 | AE276: 23.7 | AF276: 29.732 | AG276: 71.556 | AH276: 70.029 | AI276: 3.795 | AJ276: 40.094 | AK276: 9.95 | AL276: -7.48 | AM276: 70.029 | AN276: 71.556 | AO276: 29.732 | AP276: 7.48 | AQ276: 59.906 | AR276: 96.205 | AS276: 90.05
A277: 52 | B277: -10 | C277: 0 | D277: 2019 | E277: 2 | F277: =IFERROR(VLOOKUP(G277, Map!$A$1:$B$33, 2, FALSE),"WAS") -> WAS | H277: =IFERROR(VLOOKUP(I277, Map!$A$1:$B$33, 2, FALSE),"WAS") -> DAL | I277: Cowboys | J277: 28 | K277: 6 | L277: 0 | M277: 0 | N277: 40.692308 | O277: 4.7692308 | P277: 6 | Q277: 46 | R277: 25.1 | S277: 30.9 | T277: 21 | U277: 27.5 | V277: 0.7 | W277: 0 | X277: 4 | Y277: 0.7 | Z277: 9.8 | AA277: 23.8 | AB277: 286 | AC277: 70 | AD277: 15.2 | AE277: 6 | AF277: 39.022 | AG277: 39.847 | AH277: 60.664 | AI277: 10.857 | AJ277: 48.289 | AK277: 19.174 | AL277: -3.886 | AM277: 60.664 | AN277: 39.847 | AO277: 39.022 | AP277: 3.886 | AQ277: 51.711 | AR277: 89.143 | AS277: 80.826
A278: 25 | B278: 1 | C278: 1 | D278: 2019 | E278: 2 | F278: =IFERROR(VLOOKUP(G278, Map!$A$1:$B$33, 2, FALSE),"WAS") -> HOU | G278: Texans | H278: =IFERROR(VLOOKUP(I278, Map!$A$1:$B$33, 2, FALSE),"WAS") -> JAX | I278: Jaguars | J278: 34 | K278: 30 | L278: 1 | M278: 0 | N278: 35.615385 | O278: -5.5769231 | P278: -7 | Q278: 23.5 | R278: 28.9 | S278: 34.1 | T278: 24.3 | U278: 32.1 | V278: 0.7 | W278: 0 | X278: 3 | Y278: 0.7 | Z278: 18.6 | AA278: 41 | AB278: 89 | AC278: 66 | AD278: 21.3 | AE278: 10.5 | AF278: 73.671 | AG278: 44.383 | AH278: 26.119 | AI278: 83.212 | AJ278: 33.634 | AK278: 59.184 | AL278: 9.006 | AM278: 26.119 | AN278: 44.383 | AO278: 73.671 | AP278: -9.006 | AQ278: 66.366 | AR278: 16.788 | AS278: 40.816
A279: 36 | B279: 18 | C279: 1 | D279: 2019 | E279: 2 | F279: =IFERROR(VLOOKUP(G279, Map!$A$1:$B$33, 2, FALSE),"WAS") -> LA | G279: Rams | H279: =IFERROR(VLOOKUP(I279, Map!$A$1:$B$33, 2, FALSE),"WAS") -> NO | I279: Saints | J279: 14 | K279: 18 | L279: 1 | M279: 0 | N279: 43.269231 | O279: -1.5384615 | P279: -1.5 | Q279: 36.5 | R279: 24.2 | S279: 32.6 | T279: 17.1 | U279: 25.1 | V279: 0 | W279: 0 | X279: 0 | Y279: 0 | Z279: 17.1 | AA279: 34.2 | AB279: 189 | AC279: 62 | AD279: 15.9 | AE279: 7.1 | AF279: 58.47 | AG279: 88.4 | AH279: 41.199 | AI279: 90.834 | AJ279: 60.746 | AK279: 81.834 | AL279: 3.087 | AM279: 41.199 | AN279: 88.4 | AO279: 58.47 | AP279: -3.087 | AQ279: 39.254 | AR279: 9.166 | AS279: 18.166
A280: 30 | B280: -2 | C280: 0 | D280: 2019 | E280: 2 | F280: =IFERROR(VLOOKUP(G280, Map!$A$1:$B$33, 2, FALSE),"WAS") -> DEN | G280: Broncos | H280: =IFERROR(VLOOKUP(I280, Map!$A$1:$B$33, 2, FALSE),"WAS") -> CHI | I280: Bears | J280: 7 | K280: 3 | L280: 0 | M280: 0 | N280: 32.076923 | O280: 2.0769231 | P280: 2.5 | Q280: 20.5 | R280: 20.8 | S280: 32.6 | T280: 11.1 | U280: 17.7 | V280: 0 | W280: 0 | X280: 0 | Y280: 0 | Z280: 20.4 | AA280: 37.8 | AB280: 136 | AC280: 28 | AD280: 16.3 | AE280: 8 | AF280: 48.831 | AG280: 39.898 | AH280: 50.777 | AI280: 51.717 | AJ280: 49.399 | AK280: 42.555 | AL280: -0.345 | AM280: 50.777 | AN280: 39.898 | AO280: 48.831 | AP280: 0.345 | AQ280: 50.601 | AR280: 48.283 | AS280: 57.445
A281: 23 | B281: 3 | C281: 1 | D281: 2019 | E281: 2 | F281: =IFERROR(VLOOKUP(G281, Map!$A$1:$B$33, 2, FALSE),"WAS") -> DET | G281: Lions | H281: =IFERROR(VLOOKUP(I281, Map!$A$1:$B$33, 2, FALSE),"WAS") -> LAC | I281: Chargers | J281: 8 | K281: 24 | L281: 1 | M281: 0 | N281: 38.5 | O281: 0.88461538 | P281: 0 | Q281: 29.5 | R281: 19.1 | S281: 24.3 | T281: 15.1 | U281: 19.1 | V281: 5.5 | W281: 0 | X281: 4 | Y281: 5.5 | Z281: 21.8 | AA281: 38.5 | AB281: 229 | AC281: 77 | AD281: 19.8 | AE281: 10.5 | AF281: 49.683 | AG281: 41.298 | AH281: 49.918 | AI281: 45.9 | AJ281: 57.882 | AK281: 54.014 | AL281: -0.042 | AM281: 49.918 | AN281: 41.298 | AO281: 49.683 | AP281: 0.042 | AQ281: 42.118 | AR281: 54.1 | AS281: 45.986
A282: 54 | B282: -2 | C282: 0 | D282: 2019 | E282: 2 | F282: =IFERROR(VLOOKUP(G282, Map!$A$1:$B$33, 2, FALSE),"WAS") -> PIT | G282: Steelers | H282: =IFERROR(VLOOKUP(I282, Map!$A$1:$B$33, 2, FALSE),"WAS") -> SEA | I282: Seahawks | J282: 23 | K282: 26 | L282: 0 | M282: 0 | N282: 41.333333 | O282: -3.375 | P282: -4 | Q282: 45.5 | R282: 20 | S282: 27.4 | T282: 13.6 | U282: 20.8 | V282: 0 | W282: 0 | X282: 0 | Y282: 0 | Z282: 9.2 | AA282: 18.4 | AB282: 268 | AC282: 71 | AD282: 11.5 | AE282: 4.6 | AF282: 53.549 | AG282: 56.658 | AH282: 46.081 | AI282: 40.557 | AJ282: 43.044 | AK282: 37.072 | AL282: 1.326 | AM282: 46.081 | AN282: 56.658 | AO282: 53.549 | AP282: -1.326 | AQ282: 56.956 | AR282: 59.443 | AS282: 62.928
A283: 42 | B283: -14 | C283: 0 | D283: 2019 | E283: 2 | F283: =IFERROR(VLOOKUP(G283, Map!$A$1:$B$33, 2, FALSE),"WAS") -> NYG | G283: Giants | H283: =IFERROR(VLOOKUP(I283, Map!$A$1:$B$33, 2, FALSE),"WAS") -> BUF | I283: Bills | J283: 19 | K283: 2 | L283: 0 | M283: 0 | N283: 39.884615 | O283: 1.0769231 | P283: 1 | Q283: 42.5 | R283: 22.2 | S283: 27 | T283: 18.9 | U283: 24.1 | V283: 0.3 | W283: 0 | X283: 2 | Y283: 0.3 | Z283: 9.8 | AA283: 22.3 | AB283: 280 | AC283: 77 | AD283: 14.3 | AE283: 5.9 | AF283: 49.257 | AG283: 16.632 | AH283: 50.347 | AI283: 11.962 | AJ283: 36.974 | AK283: 12.419 | AL283: -0.193 | AM283: 50.347 | AN283: 16.632 | AO283: 49.257 | AP283: 0.193 | AQ283: 63.026 | AR283: 88.038 | AS283: 87.581
A284: 26 | B284: -20 | C284: 0 | D284: 2019 | E284: 2 | F284: =IFERROR(VLOOKUP(G284, Map!$A$1:$B$33, 2, FALSE),"WAS") -> NYJ | G284: Jets | H284: =IFERROR(VLOOKUP(I284, Map!$A$1:$B$33, 2, FALSE),"WAS") -> CLE | I284: Browns | J284: 20 | K284: 5 | L284: 0 | M284: 0 | N284: 39.038462 | O284: 5.1923077 | P284: 2.5 | Q284: 28.5 | R284: 19.3 | S284: 23.4 | T284: 14.3 | U284: 19.2 | V284: 0.1 | W284: 0 | X284: 1 | Y284: 0.1 | Z284: 13.7 | AA284: 29.5 | AB284: 22 | AC284: 70 | AD284: 19.6 | AE284: 9 | AF284: 58.673 | AG284: 12.979 | AH284: 40.997 | AI284: 33.641 | AJ284: 7.235 | AK284: 9.097 | AL284: 3.161 | AM284: 40.997 | AN284: 12.979 | AO284: 58.673 | AP284: -3.161 | AQ284: 92.765 | AR284: 66.359 | AS284: 90.903
A285: 40 | B285: 6 | C285: 1 | D285: 2019 | E285: 2 | F285: =IFERROR(VLOOKUP(G285, Map!$A$1:$B$33, 2, FALSE),"WAS") -> BAL | G285: Ravens | H285: =IFERROR(VLOOKUP(I285, Map!$A$1:$B$33, 2, FALSE),"WAS") -> ARI | I285: Cardinals | J285: 33 | K285: 22 | L285: 1 | M285: 0 | N285: 40 | O285: -10.884615 | P285: -12.5 | Q285: 24.5 | R285: 24.5 | S285: 29.8 | T285: 21 | U285: 27.1 | V285: 2 | W285: 0 | X285: 7 | Y285: 2 | Z285: 10.1 | AA285: 25.6 | AB285: 319 | AC285: 73 | AD285: 13.2 | AE285: 5.2 | AF285: 85.684 | AG285: 52.096 | AH285: 14.202 | AI285: 45.08 | AJ285: 76.859 | AK285: 76.176 | AL285: 15.122 | AM285: 14.202 | AN285: 52.096 | AO285: 85.684 | AP285: -15.122 | AQ285: 23.141 | AR285: 54.92 | AS285: 23.824
A286: 44 | B286: 4 | C286: 1 | D286: 2019 | E286: 2 | F286: =IFERROR(VLOOKUP(G286, Map!$A$1:$B$33, 2, FALSE),"WAS") -> ATL | G286: Falcons | H286: =IFERROR(VLOOKUP(I286, Map!$A$1:$B$33, 2, FALSE),"WAS") -> PHI | I286: Eagles | J286: 1 | K286: 21 | L286: 1 | M286: 0 | N286: 44.576923 | O286: 1 | P286: 0.5 | Q286: 15.5 | R286: 27 | S286: 33.1 | T286: 20.6 | U286: 29.5 | V286: 0 | W286: 0 | X286: 0 | Y286: 0 | Z286: 9.2 | AA286: 24.8 | AB286: 46 | AC286: 63 | AD286: 14.1 | AE286: 5.9 | AF286: 50.139 | AG286: 60.445 | AH286: 49.464 | AI286: 70.187 | AJ286: 60.666 | AK286: 65.351 | AL286: 0.12 | AM286: 49.464 | AN286: 60.445 | AO286: 50.139 | AP286: -0.12 | AQ286: 39.334 | AR286: 29.813 | AS286: 34.649
A287: 34 | B287: -6 | C287: 0 | D287: 2019 | E287: 2 | F287: =IFERROR(VLOOKUP(G287, Map!$A$1:$B$33, 2, FALSE),"WAS") -> CAR | G287: Panthers | H287: =IFERROR(VLOOKUP(I287, Map!$A$1:$B$33, 2, FALSE),"WAS") -> TB | I287: Buccaneers | J287: 29 | K287: 27 | L287: 0 | M287: 0 | N287: 40.038462 | O287: -6.0384615 | P287: -6.5 | Q287: 0 | R287: 26.2 | S287: 31 | T287: 22.4 | U287: 29.8 | V287: 4.3 | W287: 0 | X287: 10 | Y287: 4.3 | Z287: 18.8 | AA287: 38.2 | AB287: 91 | AC287: 77 | AD287: 19.2 | AE287: 8.7 | AF287: 69.125 | AG287: 42.341 | AH287: 30.629 | AI287: 59.929 | AJ287: 10.46 | AK287: 38.302 | AL287: 7.116 | AM287: 30.629 | AN287: 42.341 | AO287: 69.125 | AP287: -7.116 | AQ287: 89.54 | AR287: 40.071 | AS287: 61.698
A288: 43 | B288: -43 | C288: 0 | D288: 2019 | E288: 2 | F288: =IFERROR(VLOOKUP(G288, Map!$A$1:$B$33, 2, FALSE),"WAS") -> MIA | G288: Dolphins | H288: =IFERROR(VLOOKUP(I288, Map!$A$1:$B$33, 2, FALSE),"WAS") -> NE | I288: Patriots | J288: 15 | K288: 17 | L288: 0 | M288: 0 | N288: 41.730769 | O288: 13.846154 | P288: 17.5 | Q288: 44.5 | R288: 27.5 | S288: 31.9 | T288: 24.3 | U288: 33 | V288: 4.3 | W288: 0 | X288: 10 | Y288: 4.3 | Z288: 15 | AA288: 36.4 | AB288: 276 | AC288: 85 | AD288: 19.7 | AE288: 8.3 | AF288: 14.143 | AG288: 44.736 | AH288: 85.744 | AI288: 17.086 | AJ288: 0.181 | AK288: 1.984 | AL288: -15.16 | AM288: 85.744 | AN288: 44.736 | AO288: 14.143 | AP288: 15.16 | AQ288: 99.819 | AR288: 82.914 | AS288: 98.016
A289: 36 | B289: -2 | C289: 0 | D289: 2019 | E289: 2 | F289: =IFERROR(VLOOKUP(G289, Map!$A$1:$B$33, 2, FALSE),"WAS") -> TEN | G289: Titans | H289: =IFERROR(VLOOKUP(I289, Map!$A$1:$B$33, 2, FALSE),"WAS") -> IND | I289: Colts | J289: 10 | K289: 11 | L289: 0 | M289: 0 | N289: 37.461538 | O289: -2.9230769 | P289: -3 | Q289: 21.5 | R289: 27.2 | S289: 34.9 | T289: 20.5 | U289: 28.9 | V289: 0 | W289: 0 | X289: 0 | Y289: 0 | Z289: 9.3 | AA289: 17.3 | AB289: 59 | AC289: 52 | AD289: 12.2 | AE289: 4.6 | AF289: 65.656 | AG289: 65.19 | AH289: 34.07 | AI289: 52.197 | AJ289: 39.147 | AK289: 46.045 | AL289: 5.756 | AM289: 34.07 | AN289: 65.19 | AO289: 65.656 | AP289: -5.756 | AQ289: 60.853 | AR289: 47.803 | AS289: 53.955
...
